Workbook

Sheet README
A1: ShopKart – Module 2 solution workbook
A2: Every number in this file comes from a formula. Change a raw value and the summaries update.
A4: Sheet order (follow the videos):
A5: orders_raw – the messy export (5,055 rows). Column M flags duplicate rows (Video 2.2).
A6: orders_clean – after Data > Remove duplicates (5,000 rows). Columns M–W are helper cleaning formulas (Videos 2.2–2.4).
A7: city_map – old city spelling to standard name, used by city_clean.
A8: products, customers – lookup tables (unchanged).
A9: Summary – SUMIFS / COUNTIFS / AVERAGEIFS by city, category and month (Video 2.4).
A10: Pivot_check – formula version of the city x category pivot table built in Video 2.5.
A11: Report – one-page answer to 3 business questions with charts (Video 2.6).
A13: Colour key: dark header = data column; light orange header = helper formula column; green cells = key answers.
A14: Works in Google Sheets and Excel 365. XLOOKUP needs Excel 2021/365 or Google Sheets.

Sheet Report
A1: ShopKart 2025 – one-page report
A2: Source: orders_clean (5,000 orders after cleaning). All numbers are live formulas.
A4: Total revenue | C4: Orders | E4: Avg order value | G4: Return rate
A5: =Summary!B3 -> 14704650 | C5: =Summary!B4 -> 5000 | E5: =Summary!B5 -> 2940.9299 | G5: =Summary!B7 -> 0.1374
A7: Q1. Which city brings the most revenue?
A8: ="Answer: "&INDEX(Summary!$A$11:$A$20,MATCH(MAX(Summary!$B$11:$B$20),Summary!$B$11:$B$20,0))&" with ₹"&TEXT(MAX(Summary!$B$11:$B$20),"#,##0")&" ("&TEXT(MAX(Summary!$B$11:$B$20)/Summary!B3,"0.0%")&" of all revenue)." -> Answer: Delhi with ₹2,323,405 (15.8% of all revenue).
A10: Q2. Which month is our peak, and how big is it?
A11: ="Answer: "&INDEX(Summary!$B$33:$B$44,MATCH(MAX(Summary!$C$33:$C$44),Summary!$C$33:$C$44,0))&" with ₹"&TEXT(MAX(Summary!$C$33:$C$44),"#,##0")&", "&TEXT(MAX(Summary!$C$33:$C$44)/MIN(Summary!$C$33:$C$44),"0.0")&"x the weakest month ("&INDEX(Summary!$B$33:$B$44,MATCH(MIN(Summary!$C$33:$C$44),Summary!$C$33:$C$44,0))&")." -> Answer: Oct with ₹1,978,317, 2.5x the weakest month (May).
A13: Q3. Is any city returning far more orders than the rest?
A14: ="Answer: "&INDEX(Summary!$A$11:$A$20,MATCH(MAX(Summary!$F$11:$F$20),Summary!$F$11:$F$20,0))&" returns "&TEXT(MAX(Summary!$F$11:$F$20),"0.0%")&" of orders vs "&TEXT(Summary!B7,"0.0%")&" overall ("&TEXT(MAX(Summary!$F$11:$F$20)/Summary!B7,"0.0")&"x). Investigate delivery and products there." -> Answer: Pune returns 32.4% of orders vs 13.7% overall (2.4x). Investigate delivery and products there.

Sheet orders_raw
A1: order_id | B1: order_date | C1: customer_id | D1: product_id | E1: quantity | F1: unit_price | G1: discount | H1: city | I1: payment_mode | J1: delivery_days | K1: rating | L1: returned | M1: dup_flag | O1: Rows | P1: =COUNTA(A2:A5056) -> 5055
A2: O10001 | B2: 2025-01-01 | C2: C0593 | D2: P048 | E2: 6 | F2: 362 | G2: 0.2 | H2: Delhi | I2: COD | J2: 4 | K2: 2 | L2: N | M2: =IF(COUNTIF($A$2:A2,A2)>1,"DUPLICATE","") | O2: Duplicates | P2: =COUNTIF(M2:M5056,"DUPLICATE") -> 55
A3: O10002 | B3: 2025-01-01 | C3: C0367 | D3: P049 | E3: 2 | F3: 300 | G3: 0.05 | H3: Chennai | I3: Debit Card | J3: 4 | K3: 5 | L3: N | M3: =IF(COUNTIF($A$2:A3,A3)>1,"DUPLICATE","") | O3: Rows after removing | P3: =P1-P2 -> 5000
A4: O10003 | B4: 2025-01-01 | C4: C0707 | D4: P020 | E4: 1 | F4: 2258 | G4: 0.05 | H4: DELHI | I4: Debit Card | J4: 2 | K4: 3 | L4: N | M4: =IF(COUNTIF($A$2:A4,A4)>1,"DUPLICATE","")
A5: O10004 | B5: 2025-01-01 | C5: C0118 | D5: P026 | E5: 2 | F5: 2020 | G5: 0.15 | H5: Lucknow | I5: COD | J5: 4 | K5: 4 | L5: Y | M5: =IF(COUNTIF($A$2:A5,A5)>1,"DUPLICATE","")
A6: O10005 | B6: 2025-01-01 | C6: C0238 | D6: P026 | E6: 2 | F6: 1937 | G6: 0.1 | H6: Chennai | I6: UPI | J6: 2 | K6: 4 | L6: N | M6: =IF(COUNTIF($A$2:A6,A6)>1,"DUPLICATE","")
A7: O10006 | B7: 2025-01-01 | C7: C0561 | D7: P014 | E7: 2 | F7: 1440 | G7: 0.05 | H7: Delhi | I7: UPI | J7: 5 | K7: 4 | L7: N | M7: =IF(COUNTIF($A$2:A7,A7)>1,"DUPLICATE","")
A8: O10007 | B8: 2025-01-01 | C8: C0460 | D8: P009 | E8: 2 | F8: 15303 | G8: 0.2 | H8: Kolkata | I8: UPI | J8: 3 | K8: 5 | L8: N | M8: =IF(COUNTIF($A$2:A8,A8)>1,"DUPLICATE","")
A9: O10008 | B9: 2025-01-01 | C9: C0311 | D9: P009 | E9: 1 | F9: 14841 | G9: 0.05 | H9: Pune | I9: Credit Card | J9: 4 | K9: 4 | L9: N | M9: =IF(COUNTIF($A$2:A9,A9)>1,"DUPLICATE","")
A10: O10009 | B10: 2025-01-01 | C10: C0566 | D10: P010 | E10: 2 | F10: 18548 | G10: 0.05 | H10: Chennai | I10: Debit Card | J10: 3 | K10: 5 | L10: N | M10: =IF(COUNTIF($A$2:A10,A10)>1,"DUPLICATE","")
A11: O10010 | B11: 2025-01-01 | C11: C0454 | D11: P040 | E11: 2 | F11: 348 | G11: 0 | H11: Chennai | I11: Credit Card | J11: 3 | K11: 3 | L11: N | M11: =IF(COUNTIF($A$2:A11,A11)>1,"DUPLICATE","")
A12: O10011 | B12: 2025-01-01 | C12: C0086 | D12: P054 | E12: 2 | F12: 1494 | G12: 0 | H12: Hyderabad | I12: Debit Card | J12: 2 | K12: 4 | L12: N | M12: =IF(COUNTIF($A$2:A12,A12)>1,"DUPLICATE","")
A13: O10012 | B13: 2025-01-01 | C13: C0097 | D13: P051 | E13: 1 | F13: 248 | G13: 0.2 | H13: Delhi | I13: Credit Card | J13: 3 | K13: 4 | L13: N | M13: =IF(COUNTIF($A$2:A13,A13)>1,"DUPLICATE","")
A14: O10013 | B14: 2025-01-02 | C14: C0403 | D14: P015 | E14: 1 | F14: 3128 | G14: 0.15 | H14: Ahmedabad | I14: Credit Card | J14: 3 | K14: 4 | L14: Y | M14: =IF(COUNTIF($A$2:A14,A14)>1,"DUPLICATE","")
A15: O10014 | B15: 2025-01-02 | C15: C0663 | D15: P003 | E15: 1 | F15: 3910 | G15: 0.2 | H15: Ahmedabad | I15: UPI | J15: 5 | K15: 5 | L15: N | M15: =IF(COUNTIF($A$2:A15,A15)>1,"DUPLICATE","")
... A29: O10028 | B29: 2025-01-03 | C29: C0464 | D29: P057 | E29: 1 | F29: 335 | G29: 0.05 | H29: Bengaluru | I29: UPI | J29: 3 | K29: 4 | L29: N | M29: =IF(COUNTIF($A$2:A29,A29)>1,"DUPLICATE","")
A30: O10029 | B30: 2025-01-03 | C30: C0116 | D30: P035 | E30: 2 | F30: ₹626 | H30: Chennai | I30: Debit Card | J30: 4 | K30: 3 | L30: N | M30: =IF(COUNTIF($A$2:A30,A30)>1,"DUPLICATE","")
A31: O10030 | B31: 2025-01-03 | C31: C0016 | D31: P056 | E31: 1 | F31: 463 | G31: 0 | H31: Mumbai | I31: UPI | J31: 3 | K31: 5 | L31: N | M31: =IF(COUNTIF($A$2:A31,A31)>1,"DUPLICATE","")
A32: O10031 | B32: 2025-01-03 | C32: C0411 | D32: P023 | E32: 1 | F32: 1622 | G32: 0 | H32: Hyderabad | I32: UPI | J32: 4 | K32: 3 | L32: Y | M32: =IF(COUNTIF($A$2:A32,A32)>1,"DUPLICATE","")
A33: O10032 | B33: 2025-01-03 | C33: C0697 | D33: P021 | E33: 2 | F33: 685 | G33: 0.1 | H33: Bengaluru | I33: UPI | J33: 4 | K33: 3 | L33: N | M33: =IF(COUNTIF($A$2:A33,A33)>1,"DUPLICATE","")
A34: O10033 | B34: 2025-01-03 | C34: C0423 | D34: P023 | E34: 3 | F34: 1669 | G34: 0.05 | H34: Mumbai | I34: Debit Card | J34: 5 | K34: 5 | L34: N | M34: =IF(COUNTIF($A$2:A34,A34)>1,"DUPLICATE","")
A35: O10034 | B35: 03-01-2025 | C35: C0240 | D35: P047 | E35: 4 | F35: 1077 | G35: 0.1 | H35: Mumbai | J35: 3 | K35: 5 | L35: N | M35: =IF(COUNTIF($A$2:A35,A35)>1,"DUPLICATE","")
A36: O10035 | B36: 2025-01-03 | C36: C0797 | D36: P016 | E36: 2 | F36: 1859 | G36: 0 | H36: hyderabad | I36: Net Banking | J36: 4 | K36: 5 | L36: N | M36: =IF(COUNTIF($A$2:A36,A36)>1,"DUPLICATE","")
A37: O10036 | B37: 2025-01-04 | C37: C0631 | D37: P005 | E37: 1 | F37: 900 | G37: 0.15 | H37: Delhi | I37: UPI | J37: 4 | K37: 4 | L37: N | M37: =IF(COUNTIF($A$2:A37,A37)>1,"DUPLICATE","")
A38: O10037 | B38: 2025-01-04 | C38: C0100 | D38: P045 | E38: 2 | F38: 310 | G38: 0.1 | H38: Hyderabad | I38: UPI | J38: 3 | L38: N | M38: =IF(COUNTIF($A$2:A38,A38)>1,"DUPLICATE","")
A39: O10038 | B39: 2025-01-04 | C39: C0392 | D39: P033 | E39: 2 | F39: 3247 | G39: 0 | H39: Mumbai | I39: Credit Card | J39: 5 | K39: 5 | L39: N | M39: =IF(COUNTIF($A$2:A39,A39)>1,"DUPLICATE","")
A40: O10039 | B40: 2025-01-04 | C40: C0457 | D40: P019 | E40: 1 | F40: 1176 | G40: 0.15 | H40: Mumbai | I40: Net Banking | J40: 3 | K40: 5 | L40: No | M40: =IF(COUNTIF($A$2:A40,A40)>1,"DUPLICATE","")
A41: O10040 | B41: 2025-01-04 | C41: C0160 | D41: P020 | E41: 4 | F41: 2408 | G41: 0.2 | H41: Bengaluru | I41: Debit Card | J41: 6 | K41: 4 | L41: N | M41: =IF(COUNTIF($A$2:A41,A41)>1,"DUPLICATE","")
A42: O10041 | B42: 2025-01-04 | C42: C0178 | D42: P002 | E42: 1 | F42: ₹2,551 | G42: 0 | H42: Chennai | I42: UPI | J42: 3 | K42: 4 | L42: N | M42: =IF(COUNTIF($A$2:A42,A42)>1,"DUPLICATE","")
A43: O10042 | B43: 2025-01-05 | C43: C0191 | D43: P025 | E43: 1 | F43: 1312 | G43: 0 | H43: Delhi | I43: COD | J43: 5 | K43: 3 | L43: N | M43: =IF(COUNTIF($A$2:A43,A43)>1,"DUPLICATE","")
A44: O10043 | B44: 2025-01-05 | C44: C0300 | D44: P003 | E44: 2 | F44: 4070 | G44: 0.05 | H44: Chennai | I44: Debit Card | J44: 2 | K44: 5 | L44: N | M44: =IF(COUNTIF($A$2:A44,A44)>1,"DUPLICATE","")
A45: O10044 | B45: 2025-01-05 | C45: C0422 | D45: P016 | E45: 2 | F45: 1871 | G45: 0.2 | H45: Hyderabad | I45: UPI | J45: 4 | K45: 4 | L45: N | M45: =IF(COUNTIF($A$2:A45,A45)>1,"DUPLICATE","")
A46: O10045 | B46: 2025-01-05 | C46: C0553 | D46: P008 | E46: 1 | F46: 384 | G46: 0.2 | H46: Bengaluru | I46: UPI | J46: 5 | K46: 4 | L46: N | M46: =IF(COUNTIF($A$2:A46,A46)>1,"DUPLICATE","")
A47: O10046 | B47: 2025-01-05 | C47: C0122 | D47: P060 | E47: 1 | F47: 414 | G47: 0.1 | H47: Delhi | I47: Debit Card | J47: 6 | K47: 3 | L47: N | M47: =IF(COUNTIF($A$2:A47,A47)>1,"DUPLICATE","")
A48: O10047 | B48: 2025-01-05 | C48: C0147 | D48: P008 | E48: 1 | F48: 409 | G48: 0 | H48: Lucknow | I48: UPI | J48: 8 | K48: 2 | L48: Yes | M48: =IF(COUNTIF($A$2:A48,A48)>1,"DUPLICATE","")
A49: O10048 | B49: 2025-01-05 | C49: C0418 | D49: P008 | E49: 1 | F49: 400 | G49: 0 | H49: Bengaluru | I49: UPI | J49: 2 | L49: N | M49: =IF(COUNTIF($A$2:A49,A49)>1,"DUPLICATE","")
A50: O10049 | B50: 2025-01-05 | C50: C0075 | D50: P023 | E50: 1 | F50: 1649 | G50: 0.05 | H50: Delhi | I50: Credit Card | J50: 6 | K50: 3 | L50: Y | M50: =IF(COUNTIF($A$2:A50,A50)>1,"DUPLICATE","")
A51: O10050 | B51: 2025-01-05 | C51: C0349 | D51: P018 | E51: 2 | F51: 2447 | G51: 0 | H51: Lucknow | J51: 6 | K51: 3 | L51: Y | M51: =IF(COUNTIF($A$2:A51,A51)>1,"DUPLICATE","")
A52: O10051 | B52: 2025-01-05 | C52: C0416 | D52: P026 | E52: 1 | F52: 2044 | G52: 0 | H52: Kolkata | I52: Credit Card | J52: 2 | K52: 5 | L52: N | M52: =IF(COUNTIF($A$2:A52,A52)>1,"DUPLICATE","")
A53: O10052 | B53: 2025-01-05 | C53: C0244 | D53: P006 | E53: 1 | F53: 1518 | G53: 0.05 | H53: Jaipur | I53: COD | J53: 5 | K53: 4 | L53: N | M53: =IF(COUNTIF($A$2:A53,A53)>1,"DUPLICATE","")
...

Sheet orders_clean
A1: order_id | B1: order_date | C1: customer_id | D1: product_id | E1: quantity | F1: unit_price | G1: discount | H1: city | I1: payment_mode | J1: delivery_days | K1: rating | L1: returned | M1: order_date_clean | N1: order_month | O1: city_trim | P1: city_clean | Q1: unit_price_num | R1: quantity_clean | S1: discount_num | T1: payment_clean | U1: returned_clean | V1: revenue | W1: category
A2: O10001 | B2: 2025-01-01 | C2: C0593 | D2: P048 | E2: 6 | F2: 362 | G2: 0.2 | H2: Delhi | I2: COD | J2: 4 | K2: 2 | L2: N | M2: =IF(ISNUMBER(B2),B2,IF(MID(B2,3,1)="-",DATE(VALUE(RIGHT(B2,4)),VALUE(MID(B2,4,2)),VALUE(LEFT(B2,2))),DATE(VALUE(LEFT(B2,4)),VALUE(MID(B2,6,2)),VALUE(RIGHT(B2,2))))) -> 45658 | N2: =MONTH(M2) -> 1 | O2: =PROPER(TRIM(H2)) -> Delhi | P2: =IFERROR(VLOOKUP(O2,city_map!$A$2:$B$6,2,FALSE()),O2) -> Delhi | Q2: =IF(ISNUMBER(F2),F2,VALUE(SUBSTITUTE(SUBSTITUTE(F2,"₹",""),",",""))) -> 362 | R2: =IF(E2=99,1,E2) -> 6 | S2: =IF(G2="",0,G2) -> 0.2 | T2: =IF(I2="","Unknown",IF(I2="upi","UPI",I2)) -> COD | U2: =IF(L2="Yes","Y",IF(L2="No","N",L2)) -> N | V2: =ROUND(R2*Q2*(1-S2),2) -> 1737.6 | W2: =_xlfn.XLOOKUP(D2,products!$A$2:$A$61,products!$C$2:$C$61,"Not found") -> Books
A3: O10002 | B3: 2025-01-01 | C3: C0367 | D3: P049 | E3: 2 | F3: 300 | G3: 0.05 | H3: Chennai | I3: Debit Card | J3: 4 | K3: 5 | L3: N | M3: =IF(ISNUMBER(B3),B3,IF(MID(B3,3,1)="-",DATE(VALUE(RIGHT(B3,4)),VALUE(MID(B3,4,2)),VALUE(LEFT(B3,2))),DATE(VALUE(LEFT(B3,4)),VALUE(MID(B3,6,2)),VALUE(RIGHT(B3,2))))) -> 45658 | N3: =MONTH(M3) -> 1 | O3: =PROPER(TRIM(H3)) -> Chennai | P3: =IFERROR(VLOOKUP(O3,city_map!$A$2:$B$6,2,FALSE()),O3) -> Chennai | Q3: =IF(ISNUMBER(F3),F3,VALUE(SUBSTITUTE(SUBSTITUTE(F3,"₹",""),",",""))) -> 300 | R3: =IF(E3=99,1,E3) -> 2 | S3: =IF(G3="",0,G3) -> 0.05 | T3: =IF(I3="","Unknown",IF(I3="upi","UPI",I3)) -> Debit Card | U3: =IF(L3="Yes","Y",IF(L3="No","N",L3)) -> N | V3: =ROUND(R3*Q3*(1-S3),2) -> 570 | W3: =_xlfn.XLOOKUP(D3,products!$A$2:$A$61,products!$C$2:$C$61,"Not found") -> Beauty
A4: O10003 | B4: 2025-01-01 | C4: C0707 | D4: P020 | E4: 1 | F4: 2258 | G4: 0.05 | H4: DELHI | I4: Debit Card | J4: 2 | K4: 3 | L4: N | M4: =IF(ISNUMBER(B4),B4,IF(MID(B4,3,1)="-",DATE(VALUE(RIGHT(B4,4)),VALUE(MID(B4,4,2)),VALUE(LEFT(B4,2))),DATE(VALUE(LEFT(B4,4)),VALUE(MID(B4,6,2)),VALUE(RIGHT(B4,2))))) -> 45658 | N4: =MONTH(M4) -> 1 | O4: =PROPER(TRIM(H4)) -> Delhi | P4: =IFERROR(VLOOKUP(O4,city_map!$A$2:$B$6,2,FALSE()),O4) -> Delhi | Q4: =IF(ISNUMBER(F4),F4,VALUE(SUBSTITUTE(SUBSTITUTE(F4,"₹",""),",",""))) -> 2258 | R4: =IF(E4=99,1,E4) -> 1 | S4: =IF(G4="",0,G4) -> 0.05 | T4: =IF(I4="","Unknown",IF(I4="upi","UPI",I4)) -> Debit Card | U4: =IF(L4="Yes","Y",IF(L4="No","N",L4)) -> N | V4: =ROUND(R4*Q4*(1-S4),2) -> 2145.1 | W4: =_xlfn.XLOOKUP(D4,products!$A$2:$A$61,products!$C$2:$C$61,"Not found") -> Fashion
A5: O10004 | B5: 2025-01-01 | C5: C0118 | D5: P026 | E5: 2 | F5: 2020 | G5: 0.15 | H5: Lucknow | I5: COD | J5: 4 | K5: 4 | L5: Y | M5: =IF(ISNUMBER(B5),B5,IF(MID(B5,3,1)="-",DATE(VALUE(RIGHT(B5,4)),VALUE(MID(B5,4,2)),VALUE(LEFT(B5,2))),DATE(VALUE(LEFT(B5,4)),VALUE(MID(B5,6,2)),VALUE(RIGHT(B5,2))))) -> 45658 | N5: =MONTH(M5) -> 1 | O5: =PROPER(TRIM(H5)) -> Lucknow | P5: =IFERROR(VLOOKUP(O5,city_map!$A$2:$B$6,2,FALSE()),O5) -> Lucknow | Q5: =IF(ISNUMBER(F5),F5,VALUE(SUBSTITUTE(SUBSTITUTE(F5,"₹",""),",",""))) -> 2020 | R5: =IF(E5=99,1,E5) -> 2 | S5: =IF(G5="",0,G5) -> 0.15 | T5: =IF(I5="","Unknown",IF(I5="upi","UPI",I5)) -> COD | U5: =IF(L5="Yes","Y",IF(L5="No","N",L5)) -> Y | V5: =ROUND(R5*Q5*(1-S5),2) -> 3434 | W5: =_xlfn.XLOOKUP(D5,products!$A$2:$A$61,products!$C$2:$C$61,"Not found") -> Home
A6: O10005 | B6: 2025-01-01 | C6: C0238 | D6: P026 | E6: 2 | F6: 1937 | G6: 0.1 | H6: Chennai | I6: UPI | J6: 2 | K6: 4 | L6: N | M6: =IF(ISNUMBER(B6),B6,IF(MID(B6,3,1)="-",DATE(VALUE(RIGHT(B6,4)),VALUE(MID(B6,4,2)),VALUE(LEFT(B6,2))),DATE(VALUE(LEFT(B6,4)),VALUE(MID(B6,6,2)),VALUE(RIGHT(B6,2))))) -> 45658 | N6: =MONTH(M6) -> 1 | O6: =PROPER(TRIM(H6)) -> Chennai | P6: =IFERROR(VLOOKUP(O6,city_map!$A$2:$B$6,2,FALSE()),O6) -> Chennai | Q6: =IF(ISNUMBER(F6),F6,VALUE(SUBSTITUTE(SUBSTITUTE(F6,"₹",""),",",""))) -> 1937 | R6: =IF(E6=99,1,E6) -> 2 | S6: =IF(G6="",0,G6) -> 0.1 | T6: =IF(I6="","Unknown",IF(I6="upi","UPI",I6)) -> UPI | U6: =IF(L6="Yes","Y",IF(L6="No","N",L6)) -> N | V6: =ROUND(R6*Q6*(1-S6),2) -> 3486.6 | W6: =_xlfn.XLOOKUP(D6,products!$A$2:$A$61,products!$C$2:$C$61,"Not found") -> Home
A7: O10006 | B7: 2025-01-01 | C7: C0561 | D7: P014 | E7: 2 | F7: 1440 | G7: 0.05 | H7: Delhi | I7: UPI | J7: 5 | K7: 4 | L7: N | M7: =IF(ISNUMBER(B7),B7,IF(MID(B7,3,1)="-",DATE(VALUE(RIGHT(B7,4)),VALUE(MID(B7,4,2)),VALUE(LEFT(B7,2))),DATE(VALUE(LEFT(B7,4)),VALUE(MID(B7,6,2)),VALUE(RIGHT(B7,2))))) -> 45658 | N7: =MONTH(M7) -> 1 | O7: =PROPER(TRIM(H7)) -> Delhi | P7: =IFERROR(VLOOKUP(O7,city_map!$A$2:$B$6,2,FALSE()),O7) -> Delhi | Q7: =IF(ISNUMBER(F7),F7,VALUE(SUBSTITUTE(SUBSTITUTE(F7,"₹",""),",",""))) -> 1440 | R7: =IF(E7=99,1,E7) -> 2 | S7: =IF(G7="",0,G7) -> 0.05 | T7: =IF(I7="","Unknown",IF(I7="upi","UPI",I7)) -> UPI | U7: =IF(L7="Yes","Y",IF(L7="No","N",L7)) -> N | V7: =ROUND(R7*Q7*(1-S7),2) -> 2736 | W7: =_xlfn.XLOOKUP(D7,products!$A$2:$A$61,products!$C$2:$C$61,"Not found") -> Fashion
A8: O10007 | B8: 2025-01-01 | C8: C0460 | D8: P009 | E8: 2 | F8: 15303 | G8: 0.2 | H8: Kolkata | I8: UPI | J8: 3 | K8: 5 | L8: N | M8: =IF(ISNUMBER(B8),B8,IF(MID(B8,3,1)="-",DATE(VALUE(RIGHT(B8,4)),VALUE(MID(B8,4,2)),VALUE(LEFT(B8,2))),DATE(VALUE(LEFT(B8,4)),VALUE(MID(B8,6,2)),VALUE(RIGHT(B8,2))))) -> 45658 | N8: =MONTH(M8) -> 1 | O8: =PROPER(TRIM(H8)) -> Kolkata | P8: =IFERROR(VLOOKUP(O8,city_map!$A$2:$B$6,2,FALSE()),O8) -> Kolkata | Q8: =IF(ISNUMBER(F8),F8,VALUE(SUBSTITUTE(SUBSTITUTE(F8,"₹",""),",",""))) -> 15303 | R8: =IF(E8=99,1,E8) -> 2 | S8: =IF(G8="",0,G8) -> 0.2 | T8: =IF(I8="","Unknown",IF(I8="upi","UPI",I8)) -> UPI | U8: =IF(L8="Yes","Y",IF(L8="No","N",L8)) -> N | V8: =ROUND(R8*Q8*(1-S8),2) -> 24484.8 | W8: =_xlfn.XLOOKUP(D8,products!$A$2:$A$61,products!$C$2:$C$61,"Not found") -> Electronics
A9: O10008 | B9: 2025-01-01 | C9: C0311 | D9: P009 | E9: 1 | F9: 14841 | G9: 0.05 | H9: Pune | I9: Credit Card | J9: 4 | K9: 4 | L9: N | M9: =IF(ISNUMBER(B9),B9,IF(MID(B9,3,1)="-",DATE(VALUE(RIGHT(B9,4)),VALUE(MID(B9,4,2)),VALUE(LEFT(B9,2))),DATE(VALUE(LEFT(B9,4)),VALUE(MID(B9,6,2)),VALUE(RIGHT(B9,2))))) -> 45658 | N9: =MONTH(M9) -> 1 | O9: =PROPER(TRIM(H9)) -> Pune | P9: =IFERROR(VLOOKUP(O9,city_map!$A$2:$B$6,2,FALSE()),O9) -> Pune | Q9: =IF(ISNUMBER(F9),F9,VALUE(SUBSTITUTE(SUBSTITUTE(F9,"₹",""),",",""))) -> 14841 | R9: =IF(E9=99,1,E9) -> 1 | S9: =IF(G9="",0,G9) -> 0.05 | T9: =IF(I9="","Unknown",IF(I9="upi","UPI",I9)) -> Credit Card | U9: =IF(L9="Yes","Y",IF(L9="No","N",L9)) -> N | V9: =ROUND(R9*Q9*(1-S9),2) -> 14098.95 | W9: =_xlfn.XLOOKUP(D9,products!$A$2:$A$61,products!$C$2:$C$61,"Not found") -> Electronics
A10: O10009 | B10: 2025-01-01 | C10: C0566 | D10: P010 | E10: 2 | F10: 18548 | G10: 0.05 | H10: Chennai | I10: Debit Card | J10: 3 | K10: 5 | L10: N | M10: =IF(ISNUMBER(B10),B10,IF(MID(B10,3,1)="-",DATE(VALUE(RIGHT(B10,4)),VALUE(MID(B10,4,2)),VALUE(LEFT(B10,2))),DATE(VALUE(LEFT(B10,4)),VALUE(MID(B10,6,2)),VALUE(RIGHT(B10,2))))) -> 45658 | N10: =MONTH(M10) -> 1 | O10: =PROPER(TRIM(H10)) -> Chennai | P10: =IFERROR(VLOOKUP(O10,city_map!$A$2:$B$6,2,FALSE()),O10) -> Chennai | Q10: =IF(ISNUMBER(F10),F10,VALUE(SUBSTITUTE(SUBSTITUTE(F10,"₹",""),",",""))) -> 18548 | R10: =IF(E10=99,1,E10) -> 2 | S10: =IF(G10="",0,G10) -> 0.05 | T10: =IF(I10="","Unknown",IF(I10="upi","UPI",I10)) -> Debit Card | U10: =IF(L10="Yes","Y",IF(L10="No","N",L10)) -> N | V10: =ROUND(R10*Q10*(1-S10),2) -> 35241.2 | W10: =_xlfn.XLOOKUP(D10,products!$A$2:$A$61,products!$C$2:$C$61,"Not found") -> Electronics
A11: O10010 | B11: 2025-01-01 | C11: C0454 | D11: P040 | E11: 2 | F11: 348 | G11: 0 | H11: Chennai | I11: Credit Card | J11: 3 | K11: 3 | L11: N | M11: =IF(ISNUMBER(B11),B11,IF(MID(B11,3,1)="-",DATE(VALUE(RIGHT(B11,4)),VALUE(MID(B11,4,2)),VALUE(LEFT(B11,2))),DATE(VALUE(LEFT(B11,4)),VALUE(MID(B11,6,2)),VALUE(RIGHT(B11,2))))) -> 45658 | N11: =MONTH(M11) -> 1 | O11: =PROPER(TRIM(H11)) -> Chennai | P11: =IFERROR(VLOOKUP(O11,city_map!$A$2:$B$6,2,FALSE()),O11) -> Chennai | Q11: =IF(ISNUMBER(F11),F11,VALUE(SUBSTITUTE(SUBSTITUTE(F11,"₹",""),",",""))) -> 348 | R11: =IF(E11=99,1,E11) -> 2 | S11: =IF(G11="",0,G11) -> 0 | T11: =IF(I11="","Unknown",IF(I11="upi","UPI",I11)) -> Credit Card | U11: =IF(L11="Yes","Y",IF(L11="No","N",L11)) -> N | V11: =ROUND(R11*Q11*(1-S11),2) -> 696 | W11: =_xlfn.XLOOKUP(D11,products!$A$2:$A$61,products!$C$2:$C$61,"Not found") -> Books
A12: O10011 | B12: 2025-01-01 | C12: C0086 | D12: P054 | E12: 2 | F12: 1494 | G12: 0 | H12: Hyderabad | I12: Debit Card | J12: 2 | K12: 4 | L12: N | M12: =IF(ISNUMBER(B12),B12,IF(MID(B12,3,1)="-",DATE(VALUE(RIGHT(B12,4)),VALUE(MID(B12,4,2)),VALUE(LEFT(B12,2))),DATE(VALUE(LEFT(B12,4)),VALUE(MID(B12,6,2)),VALUE(RIGHT(B12,2))))) -> 45658 | N12: =MONTH(M12) -> 1 | O12: =PROPER(TRIM(H12)) -> Hyderabad | P12: =IFERROR(VLOOKUP(O12,city_map!$A$2:$B$6,2,FALSE()),O12) -> Hyderabad | Q12: =IF(ISNUMBER(F12),F12,VALUE(SUBSTITUTE(SUBSTITUTE(F12,"₹",""),",",""))) -> 1494 | R12: =IF(E12=99,1,E12) -> 2 | S12: =IF(G12="",0,G12) -> 0 | T12: =IF(I12="","Unknown",IF(I12="upi","UPI",I12)) -> Debit Card | U12: =IF(L12="Yes","Y",IF(L12="No","N",L12)) -> N | V12: =ROUND(R12*Q12*(1-S12),2) -> 2988 | W12: =_xlfn.XLOOKUP(D12,products!$A$2:$A$61,products!$C$2:$C$61,"Not found") -> Beauty
A13: O10012 | B13: 2025-01-01 | C13: C0097 | D13: P051 | E13: 1 | F13: 248 | G13: 0.2 | H13: Delhi | I13: Credit Card | J13: 3 | K13: 4 | L13: N | M13: =IF(ISNUMBER(B13),B13,IF(MID(B13,3,1)="-",DATE(VALUE(RIGHT(B13,4)),VALUE(MID(B13,4,2)),VALUE(LEFT(B13,2))),DATE(VALUE(LEFT(B13,4)),VALUE(MID(B13,6,2)),VALUE(RIGHT(B13,2))))) -> 45658 | N13: =MONTH(M13) -> 1 | O13: =PROPER(TRIM(H13)) -> Delhi | P13: =IFERROR(VLOOKUP(O13,city_map!$A$2:$B$6,2,FALSE()),O13) -> Delhi | Q13: =IF(ISNUMBER(F13),F13,VALUE(SUBSTITUTE(SUBSTITUTE(F13,"₹",""),",",""))) -> 248 | R13: =IF(E13=99,1,E13) -> 1 | S13: =IF(G13="",0,G13) -> 0.2 | T13: =IF(I13="","Unknown",IF(I13="upi","UPI",I13)) -> Credit Card | U13: =IF(L13="Yes","Y",IF(L13="No","N",L13)) -> N | V13: =ROUND(R13*Q13*(1-S13),2) -> 198.4 | W13: =_xlfn.XLOOKUP(D13,products!$A$2:$A$61,products!$C$2:$C$61,"Not found") -> Beauty
... A29: O10028 | B29: 2025-01-03 | C29: C0464 | D29: P057 | E29: 1 | F29: 335 | G29: 0.05 | H29: Bengaluru | I29: UPI | J29: 3 | K29: 4 | L29: N | M29: =IF(ISNUMBER(B29),B29,IF(MID(B29,3,1)="-",DATE(VALUE(RIGHT(B29,4)),VALUE(MID(B29,4,2)),VALUE(LEFT(B29,2))),DATE(VALUE(LEFT(B29,4)),VALUE(MID(B29,6,2)),VALUE(RIGHT(B29,2))))) -> 45660 | N29: =MONTH(M29) -> 1 | O29: =PROPER(TRIM(H29)) -> Bengaluru | P29: =IFERROR(VLOOKUP(O29,city_map!$A$2:$B$6,2,FALSE()),O29) -> Bengaluru | Q29: =IF(ISNUMBER(F29),F29,VALUE(SUBSTITUTE(SUBSTITUTE(F29,"₹",""),",",""))) -> 335 | R29: =IF(E29=99,1,E29) -> 1 | S29: =IF(G29="",0,G29) -> 0.05 | T29: =IF(I29="","Unknown",IF(I29="upi","UPI",I29)) -> UPI | U29: =IF(L29="Yes","Y",IF(L29="No","N",L29)) -> N | V29: =ROUND(R29*Q29*(1-S29),2) -> 318.25 | W29: =_xlfn.XLOOKUP(D29,products!$A$2:$A$61,products!$C$2:$C$61,"Not found") -> Beauty
A30: O10029 | B30: 2025-01-03 | C30: C0116 | D30: P035 | E30: 2 | F30: ₹626 | H30: Chennai | I30: Debit Card | J30: 4 | K30: 3 | L30: N | M30: =IF(ISNUMBER(B30),B30,IF(MID(B30,3,1)="-",DATE(VALUE(RIGHT(B30,4)),VALUE(MID(B30,4,2)),VALUE(LEFT(B30,2))),DATE(VALUE(LEFT(B30,4)),VALUE(MID(B30,6,2)),VALUE(RIGHT(B30,2))))) -> 45660 | N30: =MONTH(M30) -> 1 | O30: =PROPER(TRIM(H30)) -> Chennai | P30: =IFERROR(VLOOKUP(O30,city_map!$A$2:$B$6,2,FALSE()),O30) -> Chennai | Q30: =IF(ISNUMBER(F30),F30,VALUE(SUBSTITUTE(SUBSTITUTE(F30,"₹",""),",",""))) -> 626 | R30: =IF(E30=99,1,E30) -> 2 | S30: =IF(G30="",0,G30) -> 0 | T30: =IF(I30="","Unknown",IF(I30="upi","UPI",I30)) -> Debit Card | U30: =IF(L30="Yes","Y",IF(L30="No","N",L30)) -> N | V30: =ROUND(R30*Q30*(1-S30),2) -> 1252 | W30: =_xlfn.XLOOKUP(D30,products!$A$2:$A$61,products!$C$2:$C$61,"Not found") -> Home
A31: O10030 | B31: 2025-01-03 | C31: C0016 | D31: P056 | E31: 1 | F31: 463 | G31: 0 | H31: Mumbai | I31: UPI | J31: 3 | K31: 5 | L31: N | M31: =IF(ISNUMBER(B31),B31,IF(MID(B31,3,1)="-",DATE(VALUE(RIGHT(B31,4)),VALUE(MID(B31,4,2)),VALUE(LEFT(B31,2))),DATE(VALUE(LEFT(B31,4)),VALUE(MID(B31,6,2)),VALUE(RIGHT(B31,2))))) -> 45660 | N31: =MONTH(M31) -> 1 | O31: =PROPER(TRIM(H31)) -> Mumbai | P31: =IFERROR(VLOOKUP(O31,city_map!$A$2:$B$6,2,FALSE()),O31) -> Mumbai | Q31: =IF(ISNUMBER(F31),F31,VALUE(SUBSTITUTE(SUBSTITUTE(F31,"₹",""),",",""))) -> 463 | R31: =IF(E31=99,1,E31) -> 1 | S31: =IF(G31="",0,G31) -> 0 | T31: =IF(I31="","Unknown",IF(I31="upi","UPI",I31)) -> UPI | U31: =IF(L31="Yes","Y",IF(L31="No","N",L31)) -> N | V31: =ROUND(R31*Q31*(1-S31),2) -> 463 | W31: =_xlfn.XLOOKUP(D31,products!$A$2:$A$61,products!$C$2:$C$61,"Not found") -> Beauty
A32: O10031 | B32: 2025-01-03 | C32: C0411 | D32: P023 | E32: 1 | F32: 1622 | G32: 0 | H32: Hyderabad | I32: UPI | J32: 4 | K32: 3 | L32: Y | M32: =IF(ISNUMBER(B32),B32,IF(MID(B32,3,1)="-",DATE(VALUE(RIGHT(B32,4)),VALUE(MID(B32,4,2)),VALUE(LEFT(B32,2))),DATE(VALUE(LEFT(B32,4)),VALUE(MID(B32,6,2)),VALUE(RIGHT(B32,2))))) -> 45660 | N32: =MONTH(M32) -> 1 | O32: =PROPER(TRIM(H32)) -> Hyderabad | P32: =IFERROR(VLOOKUP(O32,city_map!$A$2:$B$6,2,FALSE()),O32) -> Hyderabad | Q32: =IF(ISNUMBER(F32),F32,VALUE(SUBSTITUTE(SUBSTITUTE(F32,"₹",""),",",""))) -> 1622 | R32: =IF(E32=99,1,E32) -> 1 | S32: =IF(G32="",0,G32) -> 0 | T32: =IF(I32="","Unknown",IF(I32="upi","UPI",I32)) -> UPI | U32: =IF(L32="Yes","Y",IF(L32="No","N",L32)) -> Y | V32: =ROUND(R32*Q32*(1-S32),2) -> 1622 | W32: =_xlfn.XLOOKUP(D32,products!$A$2:$A$61,products!$C$2:$C$61,"Not found") -> Fashion
A33: O10032 | B33: 2025-01-03 | C33: C0697 | D33: P021 | E33: 2 | F33: 685 | G33: 0.1 | H33: Bengaluru | I33: UPI | J33: 4 | K33: 3 | L33: N | M33: =IF(ISNUMBER(B33),B33,IF(MID(B33,3,1)="-",DATE(VALUE(RIGHT(B33,4)),VALUE(MID(B33,4,2)),VALUE(LEFT(B33,2))),DATE(VALUE(LEFT(B33,4)),VALUE(MID(B33,6,2)),VALUE(RIGHT(B33,2))))) -> 45660 | N33: =MONTH(M33) -> 1 | O33: =PROPER(TRIM(H33)) -> Bengaluru | P33: =IFERROR(VLOOKUP(O33,city_map!$A$2:$B$6,2,FALSE()),O33) -> Bengaluru | Q33: =IF(ISNUMBER(F33),F33,VALUE(SUBSTITUTE(SUBSTITUTE(F33,"₹",""),",",""))) -> 685 | R33: =IF(E33=99,1,E33) -> 2 | S33: =IF(G33="",0,G33) -> 0.1 | T33: =IF(I33="","Unknown",IF(I33="upi","UPI",I33)) -> UPI | U33: =IF(L33="Yes","Y",IF(L33="No","N",L33)) -> N | V33: =ROUND(R33*Q33*(1-S33),2) -> 1233 | W33: =_xlfn.XLOOKUP(D33,products!$A$2:$A$61,products!$C$2:$C$61,"Not found") -> Fashion
A34: O10033 | B34: 2025-01-03 | C34: C0423 | D34: P023 | E34: 3 | F34: 1669 | G34: 0.05 | H34: Mumbai | I34: Debit Card | J34: 5 | K34: 5 | L34: N | M34: =IF(ISNUMBER(B34),B34,IF(MID(B34,3,1)="-",DATE(VALUE(RIGHT(B34,4)),VALUE(MID(B34,4,2)),VALUE(LEFT(B34,2))),DATE(VALUE(LEFT(B34,4)),VALUE(MID(B34,6,2)),VALUE(RIGHT(B34,2))))) -> 45660 | N34: =MONTH(M34) -> 1 | O34: =PROPER(TRIM(H34)) -> Mumbai | P34: =IFERROR(VLOOKUP(O34,city_map!$A$2:$B$6,2,FALSE()),O34) -> Mumbai | Q34: =IF(ISNUMBER(F34),F34,VALUE(SUBSTITUTE(SUBSTITUTE(F34,"₹",""),",",""))) -> 1669 | R34: =IF(E34=99,1,E34) -> 3 | S34: =IF(G34="",0,G34) -> 0.05 | T34: =IF(I34="","Unknown",IF(I34="upi","UPI",I34)) -> Debit Card | U34: =IF(L34="Yes","Y",IF(L34="No","N",L34)) -> N | V34: =ROUND(R34*Q34*(1-S34),2) -> 4756.65 | W34: =_xlfn.XLOOKUP(D34,products!$A$2:$A$61,products!$C$2:$C$61,"Not found") -> Fashion
A35: O10034 | B35: 03-01-2025 | C35: C0240 | D35: P047 | E35: 4 | F35: 1077 | G35: 0.1 | H35: Mumbai | J35: 3 | K35: 5 | L35: N | M35: =IF(ISNUMBER(B35),B35,IF(MID(B35,3,1)="-",DATE(VALUE(RIGHT(B35,4)),VALUE(MID(B35,4,2)),VALUE(LEFT(B35,2))),DATE(VALUE(LEFT(B35,4)),VALUE(MID(B35,6,2)),VALUE(RIGHT(B35,2))))) -> 45660 | N35: =MONTH(M35) -> 1 | O35: =PROPER(TRIM(H35)) -> Mumbai | P35: =IFERROR(VLOOKUP(O35,city_map!$A$2:$B$6,2,FALSE()),O35) -> Mumbai | Q35: =IF(ISNUMBER(F35),F35,VALUE(SUBSTITUTE(SUBSTITUTE(F35,"₹",""),",",""))) -> 1077 | R35: =IF(E35=99,1,E35) -> 4 | S35: =IF(G35="",0,G35) -> 0.1 | T35: =IF(I35="","Unknown",IF(I35="upi","UPI",I35)) -> Unknown | U35: =IF(L35="Yes","Y",IF(L35="No","N",L35)) -> N | V35: =ROUND(R35*Q35*(1-S35),2) -> 3877.2 | W35: =_xlfn.XLOOKUP(D35,products!$A$2:$A$61,products!$C$2:$C$61,"Not found") -> Books
A36: O10035 | B36: 2025-01-03 | C36: C0797 | D36: P016 | E36: 2 | F36: 1859 | G36: 0 | H36: hyderabad | I36: Net Banking | J36: 4 | K36: 5 | L36: N | M36: =IF(ISNUMBER(B36),B36,IF(MID(B36,3,1)="-",DATE(VALUE(RIGHT(B36,4)),VALUE(MID(B36,4,2)),VALUE(LEFT(B36,2))),DATE(VALUE(LEFT(B36,4)),VALUE(MID(B36,6,2)),VALUE(RIGHT(B36,2))))) -> 45660 | N36: =MONTH(M36) -> 1 | O36: =PROPER(TRIM(H36)) -> Hyderabad | P36: =IFERROR(VLOOKUP(O36,city_map!$A$2:$B$6,2,FALSE()),O36) -> Hyderabad | Q36: =IF(ISNUMBER(F36),F36,VALUE(SUBSTITUTE(SUBSTITUTE(F36,"₹",""),",",""))) -> 1859 | R36: =IF(E36=99,1,E36) -> 2 | S36: =IF(G36="",0,G36) -> 0 | T36: =IF(I36="","Unknown",IF(I36="upi","UPI",I36)) -> Net Banking | U36: =IF(L36="Yes","Y",IF(L36="No","N",L36)) -> N | V36: =ROUND(R36*Q36*(1-S36),2) -> 3718 | W36: =_xlfn.XLOOKUP(D36,products!$A$2:$A$61,products!$C$2:$C$61,"Not found") -> Fashion
A37: O10036 | B37: 2025-01-04 | C37: C0631 | D37: P005 | E37: 1 | F37: 900 | G37: 0.15 | H37: Delhi | I37: UPI | J37: 4 | K37: 4 | L37: N | M37: =IF(ISNUMBER(B37),B37,IF(MID(B37,3,1)="-",DATE(VALUE(RIGHT(B37,4)),VALUE(MID(B37,4,2)),VALUE(LEFT(B37,2))),DATE(VALUE(LEFT(B37,4)),VALUE(MID(B37,6,2)),VALUE(RIGHT(B37,2))))) -> 45661 | N37: =MONTH(M37) -> 1 | O37: =PROPER(TRIM(H37)) -> Delhi | P37: =IFERROR(VLOOKUP(O37,city_map!$A$2:$B$6,2,FALSE()),O37) -> Delhi | Q37: =IF(ISNUMBER(F37),F37,VALUE(SUBSTITUTE(SUBSTITUTE(F37,"₹",""),",",""))) -> 900 | R37: =IF(E37=99,1,E37) -> 1 | S37: =IF(G37="",0,G37) -> 0.15 | T37: =IF(I37="","Unknown",IF(I37="upi","UPI",I37)) -> UPI | U37: =IF(L37="Yes","Y",IF(L37="No","N",L37)) -> N | V37: =ROUND(R37*Q37*(1-S37),2) -> 765 | W37: =_xlfn.XLOOKUP(D37,products!$A$2:$A$61,products!$C$2:$C$61,"Not found") -> Electronics
A38: O10037 | B38: 2025-01-04 | C38: C0100 | D38: P045 | E38: 2 | F38: 310 | G38: 0.1 | H38: Hyderabad | I38: UPI | J38: 3 | L38: N | M38: =IF(ISNUMBER(B38),B38,IF(MID(B38,3,1)="-",DATE(VALUE(RIGHT(B38,4)),VALUE(MID(B38,4,2)),VALUE(LEFT(B38,2))),DATE(VALUE(LEFT(B38,4)),VALUE(MID(B38,6,2)),VALUE(RIGHT(B38,2))))) -> 45661 | N38: =MONTH(M38) -> 1 | O38: =PROPER(TRIM(H38)) -> Hyderabad | P38: =IFERROR(VLOOKUP(O38,city_map!$A$2:$B$6,2,FALSE()),O38) -> Hyderabad | Q38: =IF(ISNUMBER(F38),F38,VALUE(SUBSTITUTE(SUBSTITUTE(F38,"₹",""),",",""))) -> 310 | R38: =IF(E38=99,1,E38) -> 2 | S38: =IF(G38="",0,G38) -> 0.1 | T38: =IF(I38="","Unknown",IF(I38="upi","UPI",I38)) -> UPI | U38: =IF(L38="Yes","Y",IF(L38="No","N",L38)) -> N | V38: =ROUND(R38*Q38*(1-S38),2) -> 558 | W38: =_xlfn.XLOOKUP(D38,products!$A$2:$A$61,products!$C$2:$C$61,"Not found") -> Books
A39: O10038 | B39: 2025-01-04 | C39: C0392 | D39: P033 | E39: 2 | F39: 3247 | G39: 0 | H39: Mumbai | I39: Credit Card | J39: 5 | K39: 5 | L39: N | M39: =IF(ISNUMBER(B39),B39,IF(MID(B39,3,1)="-",DATE(VALUE(RIGHT(B39,4)),VALUE(MID(B39,4,2)),VALUE(LEFT(B39,2))),DATE(VALUE(LEFT(B39,4)),VALUE(MID(B39,6,2)),VALUE(RIGHT(B39,2))))) -> 45661 | N39: =MONTH(M39) -> 1 | O39: =PROPER(TRIM(H39)) -> Mumbai | P39: =IFERROR(VLOOKUP(O39,city_map!$A$2:$B$6,2,FALSE()),O39) -> Mumbai | Q39: =IF(ISNUMBER(F39),F39,VALUE(SUBSTITUTE(SUBSTITUTE(F39,"₹",""),",",""))) -> 3247 | R39: =IF(E39=99,1,E39) -> 2 | S39: =IF(G39="",0,G39) -> 0 | T39: =IF(I39="","Unknown",IF(I39="upi","UPI",I39)) -> Credit Card | U39: =IF(L39="Yes","Y",IF(L39="No","N",L39)) -> N | V39: =ROUND(R39*Q39*(1-S39),2) -> 6494 | W39: =_xlfn.XLOOKUP(D39,products!$A$2:$A$61,products!$C$2:$C$61,"Not found") -> Home
A40: O10039 | B40: 2025-01-04 | C40: C0457 | D40: P019 | E40: 1 | F40: 1176 | G40: 0.15 | H40: Mumbai | I40: Net Banking | J40: 3 | K40: 5 | L40: No | M40: =IF(ISNUMBER(B40),B40,IF(MID(B40,3,1)="-",DATE(VALUE(RIGHT(B40,4)),VALUE(MID(B40,4,2)),VALUE(LEFT(B40,2))),DATE(VALUE(LEFT(B40,4)),VALUE(MID(B40,6,2)),VALUE(RIGHT(B40,2))))) -> 45661 | N40: =MONTH(M40) -> 1 | O40: =PROPER(TRIM(H40)) -> Mumbai | P40: =IFERROR(VLOOKUP(O40,city_map!$A$2:$B$6,2,FALSE()),O40) -> Mumbai | Q40: =IF(ISNUMBER(F40),F40,VALUE(SUBSTITUTE(SUBSTITUTE(F40,"₹",""),",",""))) -> 1176 | R40: =IF(E40=99,1,E40) -> 1 | S40: =IF(G40="",0,G40) -> 0.15 | T40: =IF(I40="","Unknown",IF(I40="upi","UPI",I40)) -> Net Banking | U40: =IF(L40="Yes","Y",IF(L40="No","N",L40)) -> N | V40: =ROUND(R40*Q40*(1-S40),2) -> 999.6 | W40: =_xlfn.XLOOKUP(D40,products!$A$2:$A$61,products!$C$2:$C$61,"Not found") -> Fashion
A41: O10040 | B41: 2025-01-04 | C41: C0160 | D41: P020 | E41: 4 | F41: 2408 | G41: 0.2 | H41: Bengaluru | I41: Debit Card | J41: 6 | K41: 4 | L41: N | M41: =IF(ISNUMBER(B41),B41,IF(MID(B41,3,1)="-",DATE(VALUE(RIGHT(B41,4)),VALUE(MID(B41,4,2)),VALUE(LEFT(B41,2))),DATE(VALUE(LEFT(B41,4)),VALUE(MID(B41,6,2)),VALUE(RIGHT(B41,2))))) -> 45661 | N41: =MONTH(M41) -> 1 | O41: =PROPER(TRIM(H41)) -> Bengaluru | P41: =IFERROR(VLOOKUP(O41,city_map!$A$2:$B$6,2,FALSE()),O41) -> Bengaluru | Q41: =IF(ISNUMBER(F41),F41,VALUE(SUBSTITUTE(SUBSTITUTE(F41,"₹",""),",",""))) -> 2408 | R41: =IF(E41=99,1,E41) -> 4 | S41: =IF(G41="",0,G41) -> 0.2 | T41: =IF(I41="","Unknown",IF(I41="upi","UPI",I41)) -> Debit Card | U41: =IF(L41="Yes","Y",IF(L41="No","N",L41)) -> N | V41: =ROUND(R41*Q41*(1-S41),2) -> 7705.6 | W41: =_xlfn.XLOOKUP(D41,products!$A$2:$A$61,products!$C$2:$C$61,"Not found") -> Fashion
A42: O10041 | B42: 2025-01-04 | C42: C0178 | D42: P002 | E42: 1 | F42: ₹2,551 | G42: 0 | H42: Chennai | I42: UPI | J42: 3 | K42: 4 | L42: N | M42: =IF(ISNUMBER(B42),B42,IF(MID(B42,3,1)="-",DATE(VALUE(RIGHT(B42,4)),VALUE(MID(B42,4,2)),VALUE(LEFT(B42,2))),DATE(VALUE(LEFT(B42,4)),VALUE(MID(B42,6,2)),VALUE(RIGHT(B42,2))))) -> 45661 | N42: =MONTH(M42) -> 1 | O42: =PROPER(TRIM(H42)) -> Chennai | P42: =IFERROR(VLOOKUP(O42,city_map!$A$2:$B$6,2,FALSE()),O42) -> Chennai | Q42: =IF(ISNUMBER(F42),F42,VALUE(SUBSTITUTE(SUBSTITUTE(F42,"₹",""),",",""))) -> 2551 | R42: =IF(E42=99,1,E42) -> 1 | S42: =IF(G42="",0,G42) -> 0 | T42: =IF(I42="","Unknown",IF(I42="upi","UPI",I42)) -> UPI | U42: =IF(L42="Yes","Y",IF(L42="No","N",L42)) -> N | V42: =ROUND(R42*Q42*(1-S42),2) -> 2551 | W42: =_xlfn.XLOOKUP(D42,products!$A$2:$A$61,products!$C$2:$C$61,"Not found") -> Electronics
A43: O10042 | B43: 2025-01-05 | C43: C0191 | D43: P025 | E43: 1 | F43: 1312 | G43: 0 | H43: Delhi | I43: COD | J43: 5 | K43: 3 | L43: N | M43: =IF(ISNUMBER(B43),B43,IF(MID(B43,3,1)="-",DATE(VALUE(RIGHT(B43,4)),VALUE(MID(B43,4,2)),VALUE(LEFT(B43,2))),DATE(VALUE(LEFT(B43,4)),VALUE(MID(B43,6,2)),VALUE(RIGHT(B43,2))))) -> 45662 | N43: =MONTH(M43) -> 1 | O43: =PROPER(TRIM(H43)) -> Delhi | P43: =IFERROR(VLOOKUP(O43,city_map!$A$2:$B$6,2,FALSE()),O43) -> Delhi | Q43: =IF(ISNUMBER(F43),F43,VALUE(SUBSTITUTE(SUBSTITUTE(F43,"₹",""),",",""))) -> 1312 | R43: =IF(E43=99,1,E43) -> 1 | S43: =IF(G43="",0,G43) -> 0 | T43: =IF(I43="","Unknown",IF(I43="upi","UPI",I43)) -> COD | U43: =IF(L43="Yes","Y",IF(L43="No","N",L43)) -> N | V43: =ROUND(R43*Q43*(1-S43),2) -> 1312 | W43: =_xlfn.XLOOKUP(D43,products!$A$2:$A$61,products!$C$2:$C$61,"Not found") -> Home
A44: O10043 | B44: 2025-01-05 | C44: C0300 | D44: P003 | E44: 2 | F44: 4070 | G44: 0.05 | H44: Chennai | I44: Debit Card | J44: 2 | K44: 5 | L44: N | M44: =IF(ISNUMBER(B44),B44,IF(MID(B44,3,1)="-",DATE(VALUE(RIGHT(B44,4)),VALUE(MID(B44,4,2)),VALUE(LEFT(B44,2))),DATE(VALUE(LEFT(B44,4)),VALUE(MID(B44,6,2)),VALUE(RIGHT(B44,2))))) -> 45662 | N44: =MONTH(M44) -> 1 | O44: =PROPER(TRIM(H44)) -> Chennai | P44: =IFERROR(VLOOKUP(O44,city_map!$A$2:$B$6,2,FALSE()),O44) -> Chennai | Q44: =IF(ISNUMBER(F44),F44,VALUE(SUBSTITUTE(SUBSTITUTE(F44,"₹",""),",",""))) -> 4070 | R44: =IF(E44=99,1,E44) -> 2 | S44: =IF(G44="",0,G44) -> 0.05 | T44: =IF(I44="","Unknown",IF(I44="upi","UPI",I44)) -> Debit Card | U44: =IF(L44="Yes","Y",IF(L44="No","N",L44)) -> N | V44: =ROUND(R44*Q44*(1-S44),2) -> 7733 | W44: =_xlfn.XLOOKUP(D44,products!$A$2:$A$61,products!$C$2:$C$61,"Not found") -> Electronics
A45: O10044 | B45: 2025-01-05 | C45: C0422 | D45: P016 | E45: 2 | F45: 1871 | G45: 0.2 | H45: Hyderabad | I45: UPI | J45: 4 | K45: 4 | L45: N | M45: =IF(ISNUMBER(B45),B45,IF(MID(B45,3,1)="-",DATE(VALUE(RIGHT(B45,4)),VALUE(MID(B45,4,2)),VALUE(LEFT(B45,2))),DATE(VALUE(LEFT(B45,4)),VALUE(MID(B45,6,2)),VALUE(RIGHT(B45,2))))) -> 45662 | N45: =MONTH(M45) -> 1 | O45: =PROPER(TRIM(H45)) -> Hyderabad | P45: =IFERROR(VLOOKUP(O45,city_map!$A$2:$B$6,2,FALSE()),O45) -> Hyderabad | Q45: =IF(ISNUMBER(F45),F45,VALUE(SUBSTITUTE(SUBSTITUTE(F45,"₹",""),",",""))) -> 1871 | R45: =IF(E45=99,1,E45) -> 2 | S45: =IF(G45="",0,G45) -> 0.2 | T45: =IF(I45="","Unknown",IF(I45="upi","UPI",I45)) -> UPI | U45: =IF(L45="Yes","Y",IF(L45="No","N",L45)) -> N | V45: =ROUND(R45*Q45*(1-S45),2) -> 2993.6 | W45: =_xlfn.XLOOKUP(D45,products!$A$2:$A$61,products!$C$2:$C$61,"Not found") -> Fashion
A46: O10045 | B46: 2025-01-05 | C46: C0553 | D46: P008 | E46: 1 | F46: 384 | G46: 0.2 | H46: Bengaluru | I46: UPI | J46: 5 | K46: 4 | L46: N | M46: =IF(ISNUMBER(B46),B46,IF(MID(B46,3,1)="-",DATE(VALUE(RIGHT(B46,4)),VALUE(MID(B46,4,2)),VALUE(LEFT(B46,2))),DATE(VALUE(LEFT(B46,4)),VALUE(MID(B46,6,2)),VALUE(RIGHT(B46,2))))) -> 45662 | N46: =MONTH(M46) -> 1 | O46: =PROPER(TRIM(H46)) -> Bengaluru | P46: =IFERROR(VLOOKUP(O46,city_map!$A$2:$B$6,2,FALSE()),O46) -> Bengaluru | Q46: =IF(ISNUMBER(F46),F46,VALUE(SUBSTITUTE(SUBSTITUTE(F46,"₹",""),",",""))) -> 384 | R46: =IF(E46=99,1,E46) -> 1 | S46: =IF(G46="",0,G46) -> 0.2 | T46: =IF(I46="","Unknown",IF(I46="upi","UPI",I46)) -> UPI | U46: =IF(L46="Yes","Y",IF(L46="No","N",L46)) -> N | V46: =ROUND(R46*Q46*(1-S46),2) -> 307.2 | W46: =_xlfn.XLOOKUP(D46,products!$A$2:$A$61,products!$C$2:$C$61,"Not found") -> Electronics
A47: O10046 | B47: 2025-01-05 | C47: C0122 | D47: P060 | E47: 1 | F47: 414 | G47: 0.1 | H47: Delhi | I47: Debit Card | J47: 6 | K47: 3 | L47: N | M47: =IF(ISNUMBER(B47),B47,IF(MID(B47,3,1)="-",DATE(VALUE(RIGHT(B47,4)),VALUE(MID(B47,4,2)),VALUE(LEFT(B47,2))),DATE(VALUE(LEFT(B47,4)),VALUE(MID(B47,6,2)),VALUE(RIGHT(B47,2))))) -> 45662 | N47: =MONTH(M47) -> 1 | O47: =PROPER(TRIM(H47)) -> Delhi | P47: =IFERROR(VLOOKUP(O47,city_map!$A$2:$B$6,2,FALSE()),O47) -> Delhi | Q47: =IF(ISNUMBER(F47),F47,VALUE(SUBSTITUTE(SUBSTITUTE(F47,"₹",""),",",""))) -> 414 | R47: =IF(E47=99,1,E47) -> 1 | S47: =IF(G47="",0,G47) -> 0.1 | T47: =IF(I47="","Unknown",IF(I47="upi","UPI",I47)) -> Debit Card | U47: =IF(L47="Yes","Y",IF(L47="No","N",L47)) -> N | V47: =ROUND(R47*Q47*(1-S47),2) -> 372.6 | W47: =_xlfn.XLOOKUP(D47,products!$A$2:$A$61,products!$C$2:$C$61,"Not found") -> Beauty
A48: O10047 | B48: 2025-01-05 | C48: C0147 | D48: P008 | E48: 1 | F48: 409 | G48: 0 | H48: Lucknow | I48: UPI | J48: 8 | K48: 2 | L48: Yes | M48: =IF(ISNUMBER(B48),B48,IF(MID(B48,3,1)="-",DATE(VALUE(RIGHT(B48,4)),VALUE(MID(B48,4,2)),VALUE(LEFT(B48,2))),DATE(VALUE(LEFT(B48,4)),VALUE(MID(B48,6,2)),VALUE(RIGHT(B48,2))))) -> 45662 | N48: =MONTH(M48) -> 1 | O48: =PROPER(TRIM(H48)) -> Lucknow | P48: =IFERROR(VLOOKUP(O48,city_map!$A$2:$B$6,2,FALSE()),O48) -> Lucknow | Q48: =IF(ISNUMBER(F48),F48,VALUE(SUBSTITUTE(SUBSTITUTE(F48,"₹",""),",",""))) -> 409 | R48: =IF(E48=99,1,E48) -> 1 | S48: =IF(G48="",0,G48) -> 0 | T48: =IF(I48="","Unknown",IF(I48="upi","UPI",I48)) -> UPI | U48: =IF(L48="Yes","Y",IF(L48="No","N",L48)) -> Y | V48: =ROUND(R48*Q48*(1-S48),2) -> 409 | W48: =_xlfn.XLOOKUP(D48,products!$A$2:$A$61,products!$C$2:$C$61,"Not found") -> Electronics
A49: O10048 | B49: 2025-01-05 | C49: C0418 | D49: P008 | E49: 1 | F49: 400 | G49: 0 | H49: Bengaluru | I49: UPI | J49: 2 | L49: N | M49: =IF(ISNUMBER(B49),B49,IF(MID(B49,3,1)="-",DATE(VALUE(RIGHT(B49,4)),VALUE(MID(B49,4,2)),VALUE(LEFT(B49,2))),DATE(VALUE(LEFT(B49,4)),VALUE(MID(B49,6,2)),VALUE(RIGHT(B49,2))))) -> 45662 | N49: =MONTH(M49) -> 1 | O49: =PROPER(TRIM(H49)) -> Bengaluru | P49: =IFERROR(VLOOKUP(O49,city_map!$A$2:$B$6,2,FALSE()),O49) -> Bengaluru | Q49: =IF(ISNUMBER(F49),F49,VALUE(SUBSTITUTE(SUBSTITUTE(F49,"₹",""),",",""))) -> 400 | R49: =IF(E49=99,1,E49) -> 1 | S49: =IF(G49="",0,G49) -> 0 | T49: =IF(I49="","Unknown",IF(I49="upi","UPI",I49)) -> UPI | U49: =IF(L49="Yes","Y",IF(L49="No","N",L49)) -> N | V49: =ROUND(R49*Q49*(1-S49),2) -> 400 | W49: =_xlfn.XLOOKUP(D49,products!$A$2:$A$61,products!$C$2:$C$61,"Not found") -> Electronics
A50: O10049 | B50: 2025-01-05 | C50: C0075 | D50: P023 | E50: 1 | F50: 1649 | G50: 0.05 | H50: Delhi | I50: Credit Card | J50: 6 | K50: 3 | L50: Y | M50: =IF(ISNUMBER(B50),B50,IF(MID(B50,3,1)="-",DATE(VALUE(RIGHT(B50,4)),VALUE(MID(B50,4,2)),VALUE(LEFT(B50,2))),DATE(VALUE(LEFT(B50,4)),VALUE(MID(B50,6,2)),VALUE(RIGHT(B50,2))))) -> 45662 | N50: =MONTH(M50) -> 1 | O50: =PROPER(TRIM(H50)) -> Delhi | P50: =IFERROR(VLOOKUP(O50,city_map!$A$2:$B$6,2,FALSE()),O50) -> Delhi | Q50: =IF(ISNUMBER(F50),F50,VALUE(SUBSTITUTE(SUBSTITUTE(F50,"₹",""),",",""))) -> 1649 | R50: =IF(E50=99,1,E50) -> 1 | S50: =IF(G50="",0,G50) -> 0.05 | T50: =IF(I50="","Unknown",IF(I50="upi","UPI",I50)) -> Credit Card | U50: =IF(L50="Yes","Y",IF(L50="No","N",L50)) -> Y | V50: =ROUND(R50*Q50*(1-S50),2) -> 1566.55 | W50: =_xlfn.XLOOKUP(D50,products!$A$2:$A$61,products!$C$2:$C$61,"Not found") -> Fashion
A51: O10050 | B51: 2025-01-05 | C51: C0349 | D51: P018 | E51: 2 | F51: 2447 | G51: 0 | H51: Lucknow | J51: 6 | K51: 3 | L51: Y | M51: =IF(ISNUMBER(B51),B51,IF(MID(B51,3,1)="-",DATE(VALUE(RIGHT(B51,4)),VALUE(MID(B51,4,2)),VALUE(LEFT(B51,2))),DATE(VALUE(LEFT(B51,4)),VALUE(MID(B51,6,2)),VALUE(RIGHT(B51,2))))) -> 45662 | N51: =MONTH(M51) -> 1 | O51: =PROPER(TRIM(H51)) -> Lucknow | P51: =IFERROR(VLOOKUP(O51,city_map!$A$2:$B$6,2,FALSE()),O51) -> Lucknow | Q51: =IF(ISNUMBER(F51),F51,VALUE(SUBSTITUTE(SUBSTITUTE(F51,"₹",""),",",""))) -> 2447 | R51: =IF(E51=99,1,E51) -> 2 | S51: =IF(G51="",0,G51) -> 0 | T51: =IF(I51="","Unknown",IF(I51="upi","UPI",I51)) -> Unknown | U51: =IF(L51="Yes","Y",IF(L51="No","N",L51)) -> Y | V51: =ROUND(R51*Q51*(1-S51),2) -> 4894 | W51: =_xlfn.XLOOKUP(D51,products!$A$2:$A$61,products!$C$2:$C$61,"Not found") -> Fashion
A52: O10051 | B52: 2025-01-05 | C52: C0416 | D52: P026 | E52: 1 | F52: 2044 | G52: 0 | H52: Kolkata | I52: Credit Card | J52: 2 | K52: 5 | L52: N | M52: =IF(ISNUMBER(B52),B52,IF(MID(B52,3,1)="-",DATE(VALUE(RIGHT(B52,4)),VALUE(MID(B52,4,2)),VALUE(LEFT(B52,2))),DATE(VALUE(LEFT(B52,4)),VALUE(MID(B52,6,2)),VALUE(RIGHT(B52,2))))) -> 45662 | N52: =MONTH(M52) -> 1 | O52: =PROPER(TRIM(H52)) -> Kolkata | P52: =IFERROR(VLOOKUP(O52,city_map!$A$2:$B$6,2,FALSE()),O52) -> Kolkata | Q52: =IF(ISNUMBER(F52),F52,VALUE(SUBSTITUTE(SUBSTITUTE(F52,"₹",""),",",""))) -> 2044 | R52: =IF(E52=99,1,E52) -> 1 | S52: =IF(G52="",0,G52) -> 0 | T52: =IF(I52="","Unknown",IF(I52="upi","UPI",I52)) -> Credit Card | U52: =IF(L52="Yes","Y",IF(L52="No","N",L52)) -> N | V52: =ROUND(R52*Q52*(1-S52),2) -> 2044 | W52: =_xlfn.XLOOKUP(D52,products!$A$2:$A$61,products!$C$2:$C$61,"Not found") -> Home
A53: O10052 | B53: 2025-01-05 | C53: C0244 | D53: P006 | E53: 1 | F53: 1518 | G53: 0.05 | H53: Jaipur | I53: COD | J53: 5 | K53: 4 | L53: N | M53: =IF(ISNUMBER(B53),B53,IF(MID(B53,3,1)="-",DATE(VALUE(RIGHT(B53,4)),VALUE(MID(B53,4,2)),VALUE(LEFT(B53,2))),DATE(VALUE(LEFT(B53,4)),VALUE(MID(B53,6,2)),VALUE(RIGHT(B53,2))))) -> 45662 | N53: =MONTH(M53) -> 1 | O53: =PROPER(TRIM(H53)) -> Jaipur | P53: =IFERROR(VLOOKUP(O53,city_map!$A$2:$B$6,2,FALSE()),O53) -> Jaipur | Q53: =IF(ISNUMBER(F53),F53,VALUE(SUBSTITUTE(SUBSTITUTE(F53,"₹",""),",",""))) -> 1518 | R53: =IF(E53=99,1,E53) -> 1 | S53: =IF(G53="",0,G53) -> 0.05 | T53: =IF(I53="","Unknown",IF(I53="upi","UPI",I53)) -> COD | U53: =IF(L53="Yes","Y",IF(L53="No","N",L53)) -> N | V53: =ROUND(R53*Q53*(1-S53),2) -> 1442.1 | W53: =_xlfn.XLOOKUP(D53,products!$A$2:$A$61,products!$C$2:$C$61,"Not found") -> Electronics
A54: O10053 | B54: 2025-01-05 | C54: C0767 | D54: P017 | E54: 1 | F54: 1259 | G54: 0.15 | H54: Delhi | I54: COD | J54: 5 | K54: 3 | L54: Y | M54: =IF(ISNUMBER(B54),B54,IF(MID(B54,3,1)="-",DATE(VALUE(RIGHT(B54,4)),VALUE(MID(B54,4,2)),VALUE(LEFT(B54,2))),DATE(VALUE(LEFT(B54,4)),VALUE(MID(B54,6,2)),VALUE(RIGHT(B54,2))))) -> 45662 | N54: =MONTH(M54) -> 1 | O54: =PROPER(TRIM(H54)) -> Delhi | P54: =IFERROR(VLOOKUP(O54,city_map!$A$2:$B$6,2,FALSE()),O54) -> Delhi | Q54: =IF(ISNUMBER(F54),F54,VALUE(SUBSTITUTE(SUBSTITUTE(F54,"₹",""),",",""))) -> 1259 | R54: =IF(E54=99,1,E54) -> 1 | S54: =IF(G54="",0,G54) -> 0.15 | T54: =IF(I54="","Unknown",IF(I54="upi","UPI",I54)) -> COD | U54: =IF(L54="Yes","Y",IF(L54="No","N",L54)) -> Y | V54: =ROUND(R54*Q54*(1-S54),2) -> 1070.15 | W54: =_xlfn.XLOOKUP(D54,products!$A$2:$A$61,products!$C$2:$C$61,"Not found") -> Fashion
A55: O10054 | B55: 2025-01-05 | C55: C0531 | D55: P025 | E55: 1 | F55: 1340 | G55: 0 | H55: Chennai | I55: Credit Card | J55: 2 | K55: 4 | L55: N | M55: =IF(ISNUMBER(B55),B55,IF(MID(B55,3,1)="-",DATE(VALUE(RIGHT(B55,4)),VALUE(MID(B55,4,2)),VALUE(LEFT(B55,2))),DATE(VALUE(LEFT(B55,4)),VALUE(MID(B55,6,2)),VALUE(RIGHT(B55,2))))) -> 45662 | N55: =MONTH(M55) -> 1 | O55: =PROPER(TRIM(H55)) -> Chennai | P55: =IFERROR(VLOOKUP(O55,city_map!$A$2:$B$6,2,FALSE()),O55) -> Chennai | Q55: =IF(ISNUMBER(F55),F55,VALUE(SUBSTITUTE(SUBSTITUTE(F55,"₹",""),",",""))) -> 1340 | R55: =IF(E55=99,1,E55) -> 1 | S55: =IF(G55="",0,G55) -> 0 | T55: =IF(I55="","Unknown",IF(I55="upi","UPI",I55)) -> Credit Card | U55: =IF(L55="Yes","Y",IF(L55="No","N",L55)) -> N | V55: =ROUND(R55*Q55*(1-S55),2) -> 1340 | W55: =_xlfn.XLOOKUP(D55,products!$A$2:$A$61,products!$C$2:$C$61,"Not found") -> Home
...

Sheet city_map
A1: city_trim | B1: city_standard
A2: New Delhi | B2: Delhi
A3: Bangalore | B3: Bengaluru
A4: Bombay | B4: Mumbai
A5: Madras | B5: Chennai
A6: Calcutta | B6: Kolkata

Sheet products
A1: product_id | B1: product_name | C1: category | D1: list_price | E1: cost_price
A2: P001 | B2: Wireless Earbuds | C2: Electronics | D2: 1999 | E2: 1600
A3: P002 | B3: Bluetooth Speaker | C3: Electronics | D3: 2499 | E3: 1940
A4: P003 | B4: Smartwatch | C4: Electronics | D4: 3999 | E4: 3230
A5: P004 | B5: Power Bank 10000mAh | C5: Electronics | D5: 1299 | E5: 1030
A6: P005 | B6: USB-C Charger | C6: Electronics | D6: 899 | E6: 670
A7: P006 | B7: Gaming Mouse | C7: Electronics | D7: 1499 | E7: 1220
A8: P007 | B8: Mechanical Keyboard | C8: Electronics | D8: 3499 | E8: 2800
A9: P008 | B9: Phone Case | C9: Electronics | D9: 399 | E9: 320
A10: P009 | B10: Smartphone | C10: Electronics | D10: 14999 | E10: 11260
A11: P010 | B11: Tablet | C11: Electronics | D11: 18999 | E11: 14750
A12: P011 | B12: Laptop Stand | C12: Electronics | D12: 1199 | E12: 920
A13: P012 | B13: Webcam HD | C13: Electronics | D13: 2199 | E13: 1790
... A61: P060 | B61: Nail Polish Set | C61: Beauty | D61: 399 | E61: 190

Sheet customers
A1: customer_id | B1: name | C1: gender | D1: age | E1: city | F1: signup_date | G1: membership
A2: C0001 | B2: Neha Kapoor | C2: Female | D2: 18 | E2: Kolkata | F2: 2023-05-31 | G2: Free
A3: C0002 | B3: Sneha Das | C3: Female | D3: 36 | E3: Delhi | F3: 2023-01-16 | G3: Prime
A4: C0003 | B4: Rohit Kulkarni | C4: Male | D4: 20 | E4: Delhi | F4: 2024-07-23 | G4: Prime
A5: C0004 | B5: Nisha Khan | C5: Female | D5: 26 | E5: Kolkata | F5: 2024-12-26 | G5: Free
A6: C0005 | B6: Priya Khan | C6: Female | D6: 27 | E6: Delhi | F6: 2022-07-02 | G6: Free
A7: C0006 | B7: Siddharth Khan | C7: Male | D7: 30 | E7: Delhi | F7: 2023-06-29 | G7: Free
A8: C0007 | B8: Rohan Iyer | C8: Male | D8: 29 | E8: Bengaluru | F8: 2022-11-27 | G8: Prime
A9: C0008 | B9: Isha Reddy | C9: Female | D9: 33 | E9: Chennai | F9: 2023-05-16 | G9: Free
A10: C0009 | B10: Nisha Das | C10: Female | D10: 22 | E10: Mumbai | F10: 2024-02-24 | G10: Prime
A11: C0010 | B11: Pranav Kapoor | C11: Male | D11: 18 | E11: Mumbai | F11: 2024-06-04 | G11: Prime
A12: C0011 | B12: Ananya Gupta | C12: Female | D12: 25 | E12: Bengaluru | F12: 2024-04-10 | G12: Free
A13: C0012 | B13: Sneha Sharma | C13: Female | D13: 21 | E13: Bengaluru | F13: 2024-05-11 | G13: Free
... A801: C0800 | B801: Nisha Joshi | C801: Female | D801: 24 | E801: Mumbai | F801: 2024-04-18 | G801: Free

Sheet Summary
A1: ShopKart 2025 – summary built with SUMIFS / COUNTIFS / AVERAGEIFS
A3: Total revenue (₹) | B3: =SUM(orders_clean!$V$2:$V$5001) -> 14704650
A4: Total orders | B4: =COUNTA(orders_clean!$A$2:$A$5001) -> 5000
A5: Average order value (₹) | B5: =B3/B4 -> 2940.9299
A6: Returned orders | B6: =COUNTIF(orders_clean!$U$2:$U$5001,"Y") -> 687
A7: Overall return rate | B7: =B6/B4 -> 0.1374
A9: By city
A10: city | B10: revenue (₹) | C10: orders | D10: avg order value (₹) | E10: returns | F10: return rate
A11: Delhi | B11: =SUMIFS(orders_clean!$V$2:$V$5001,orders_clean!$P$2:$P$5001,A11) -> 2323405.4 | C11: =COUNTIFS(orders_clean!$P$2:$P$5001,A11) -> 804 | D11: =AVERAGEIFS(orders_clean!$V$2:$V$5001,orders_clean!$P$2:$P$5001,A11) -> 2889.8077 | E11: =COUNTIFS(orders_clean!$P$2:$P$5001,A11,orders_clean!$U$2:$U$5001,"Y") -> 82 | F11: =E11/C11 -> 0.10199005
A12: Bengaluru | B12: =SUMIFS(orders_clean!$V$2:$V$5001,orders_clean!$P$2:$P$5001,A12) -> 2256613.2 | C12: =COUNTIFS(orders_clean!$P$2:$P$5001,A12) -> 736 | D12: =AVERAGEIFS(orders_clean!$V$2:$V$5001,orders_clean!$P$2:$P$5001,A12) -> 3066.0506 | E12: =COUNTIFS(orders_clean!$P$2:$P$5001,A12,orders_clean!$U$2:$U$5001,"Y") -> 89 | F12: =E12/C12 -> 0.12092391
A13: Mumbai | B13: =SUMIFS(orders_clean!$V$2:$V$5001,orders_clean!$P$2:$P$5001,A13) -> 2090206 | C13: =COUNTIFS(orders_clean!$P$2:$P$5001,A13) -> 759 | D13: =AVERAGEIFS(orders_clean!$V$2:$V$5001,orders_clean!$P$2:$P$5001,A13) -> 2753.8946 | E13: =COUNTIFS(orders_clean!$P$2:$P$5001,A13,orders_clean!$U$2:$U$5001,"Y") -> 69 | F13: =E13/C13 -> 0.090909091
A14: Hyderabad | B14: =SUMIFS(orders_clean!$V$2:$V$5001,orders_clean!$P$2:$P$5001,A14) -> 1494616.8 | C14: =COUNTIFS(orders_clean!$P$2:$P$5001,A14) -> 495 | D14: =AVERAGEIFS(orders_clean!$V$2:$V$5001,orders_clean!$P$2:$P$5001,A14) -> 3019.4278 | E14: =COUNTIFS(orders_clean!$P$2:$P$5001,A14,orders_clean!$U$2:$U$5001,"Y") -> 63 | F14: =E14/C14 -> 0.12727273
A15: Pune | B15: =SUMIFS(orders_clean!$V$2:$V$5001,orders_clean!$P$2:$P$5001,A15) -> 1387698.3 | C15: =COUNTIFS(orders_clean!$P$2:$P$5001,A15) -> 451 | D15: =AVERAGEIFS(orders_clean!$V$2:$V$5001,orders_clean!$P$2:$P$5001,A15) -> 3076.9364 | E15: =COUNTIFS(orders_clean!$P$2:$P$5001,A15,orders_clean!$U$2:$U$5001,"Y") -> 146 | F15: =E15/C15 -> 0.32372506
A16: Chennai | B16: =SUMIFS(orders_clean!$V$2:$V$5001,orders_clean!$P$2:$P$5001,A16) -> 1333558.9 | C16: =COUNTIFS(orders_clean!$P$2:$P$5001,A16) -> 442 | D16: =AVERAGEIFS(orders_clean!$V$2:$V$5001,orders_clean!$P$2:$P$5001,A16) -> 3017.1016 | E16: =COUNTIFS(orders_clean!$P$2:$P$5001,A16,orders_clean!$U$2:$U$5001,"Y") -> 56 | F16: =E16/C16 -> 0.12669683
A17: Kolkata | B17: =SUMIFS(orders_clean!$V$2:$V$5001,orders_clean!$P$2:$P$5001,A17) -> 1237204.2 | C17: =COUNTIFS(orders_clean!$P$2:$P$5001,A17) -> 414 | D17: =AVERAGEIFS(orders_clean!$V$2:$V$5001,orders_clean!$P$2:$P$5001,A17) -> 2988.4159 | E17: =COUNTIFS(orders_clean!$P$2:$P$5001,A17,orders_clean!$U$2:$U$5001,"Y") -> 59 | F17: =E17/C17 -> 0.14251208
A18: Ahmedabad | B18: =SUMIFS(orders_clean!$V$2:$V$5001,orders_clean!$P$2:$P$5001,A18) -> 1065043.1 | C18: =COUNTIFS(orders_clean!$P$2:$P$5001,A18) -> 303 | D18: =AVERAGEIFS(orders_clean!$V$2:$V$5001,orders_clean!$P$2:$P$5001,A18) -> 3514.9936 | E18: =COUNTIFS(orders_clean!$P$2:$P$5001,A18,orders_clean!$U$2:$U$5001,"Y") -> 43 | F18: =E18/C18 -> 0.14191419
A19: Lucknow | B19: =SUMIFS(orders_clean!$V$2:$V$5001,orders_clean!$P$2:$P$5001,A19) -> 791223.65 | C19: =COUNTIFS(orders_clean!$P$2:$P$5001,A19) -> 326 | D19: =AVERAGEIFS(orders_clean!$V$2:$V$5001,orders_clean!$P$2:$P$5001,A19) -> 2427.0664 | E19: =COUNTIFS(orders_clean!$P$2:$P$5001,A19,orders_clean!$U$2:$U$5001,"Y") -> 44 | F19: =E19/C19 -> 0.13496933
A20: Jaipur | B20: =SUMIFS(orders_clean!$V$2:$V$5001,orders_clean!$P$2:$P$5001,A20) -> 725080.2 | C20: =COUNTIFS(orders_clean!$P$2:$P$5001,A20) -> 270 | D20: =AVERAGEIFS(orders_clean!$V$2:$V$5001,orders_clean!$P$2:$P$5001,A20) -> 2685.4822 | E20: =COUNTIFS(orders_clean!$P$2:$P$5001,A20,orders_clean!$U$2:$U$5001,"Y") -> 36 | F20: =E20/C20 -> 0.13333333
A21: Total (check) | B21: =SUM(B11:B20) -> 14704650 | C21: =SUM(C11:C20) -> 5000 | E21: =SUM(E11:E20) -> 687 | F21: =IF(AND(B21=B3,C21=B4),"OK – matches total","CHECK city names") -> OK – matches total
A23: By category
A24: category | B24: revenue (₹) | C24: orders | D24: avg order value (₹) | E24: returns | F24: return rate
A25: Electronics | B25: =SUMIFS(orders_clean!$V$2:$V$5001,orders_clean!$W$2:$W$5001,A25) -> 7331018 | C25: =COUNTIFS(orders_clean!$W$2:$W$5001,A25) -> 1152 | D25: =AVERAGEIFS(orders_clean!$V$2:$V$5001,orders_clean!$W$2:$W$5001,A25) -> 6363.7309 | E25: =COUNTIFS(orders_clean!$W$2:$W$5001,A25,orders_clean!$U$2:$U$5001,"Y") -> 155 | F25: =E25/C25 -> 0.13454861
A26: Fashion | B26: =SUMIFS(orders_clean!$V$2:$V$5001,orders_clean!$W$2:$W$5001,A26) -> 3121345.6 | C26: =COUNTIFS(orders_clean!$W$2:$W$5001,A26) -> 1326 | D26: =AVERAGEIFS(orders_clean!$V$2:$V$5001,orders_clean!$W$2:$W$5001,A26) -> 2353.956 | E26: =COUNTIFS(orders_clean!$W$2:$W$5001,A26,orders_clean!$U$2:$U$5001,"Y") -> 279 | F26: =E26/C26 -> 0.21040724
A27: Home | B27: =SUMIFS(orders_clean!$V$2:$V$5001,orders_clean!$W$2:$W$5001,A27) -> 2655047.3 | C27: =COUNTIFS(orders_clean!$W$2:$W$5001,A27) -> 1020 | D27: =AVERAGEIFS(orders_clean!$V$2:$V$5001,orders_clean!$W$2:$W$5001,A27) -> 2602.9875 | E27: =COUNTIFS(orders_clean!$W$2:$W$5001,A27,orders_clean!$U$2:$U$5001,"Y") -> 127 | F27: =E27/C27 -> 0.1245098
A28: Beauty | B28: =SUMIFS(orders_clean!$V$2:$V$5001,orders_clean!$W$2:$W$5001,A28) -> 877640.35 | C28: =COUNTIFS(orders_clean!$W$2:$W$5001,A28) -> 750 | D28: =AVERAGEIFS(orders_clean!$V$2:$V$5001,orders_clean!$W$2:$W$5001,A28) -> 1170.1871 | E28: =COUNTIFS(orders_clean!$W$2:$W$5001,A28,orders_clean!$U$2:$U$5001,"Y") -> 71 | F28: =E28/C28 -> 0.094666667
A29: Books | B29: =SUMIFS(orders_clean!$V$2:$V$5001,orders_clean!$W$2:$W$5001,A29) -> 719598.4 | C29: =COUNTIFS(orders_clean!$W$2:$W$5001,A29) -> 752 | D29: =AVERAGEIFS(orders_clean!$V$2:$V$5001,orders_clean!$W$2:$W$5001,A29) -> 956.91277 | E29: =COUNTIFS(orders_clean!$W$2:$W$5001,A29,orders_clean!$U$2:$U$5001,"Y") -> 55 | F29: =E29/C29 -> 0.073138298
A31: By month
A32: month_no | B32: month | C32: revenue (₹) | D32: orders
A33: 1 | B33: Jan | C33: =SUMIFS(orders_clean!$V$2:$V$5001,orders_clean!$N$2:$N$5001,A33) -> 1073267.1 | D33: =COUNTIFS(orders_clean!$N$2:$N$5001,A33) -> 320
A34: 2 | B34: Feb | C34: =SUMIFS(orders_clean!$V$2:$V$5001,orders_clean!$N$2:$N$5001,A34) -> 863479.5 | D34: =COUNTIFS(orders_clean!$N$2:$N$5001,A34) -> 289
A35: 3 | B35: Mar | C35: =SUMIFS(orders_clean!$V$2:$V$5001,orders_clean!$N$2:$N$5001,A35) -> 1080121.9 | D35: =COUNTIFS(orders_clean!$N$2:$N$5001,A35) -> 361
A36: 4 | B36: Apr | C36: =SUMIFS(orders_clean!$V$2:$V$5001,orders_clean!$N$2:$N$5001,A36) -> 983480.6 | D36: =COUNTIFS(orders_clean!$N$2:$N$5001,A36) -> 365
A37: 5 | B37: May | C37: =SUMIFS(orders_clean!$V$2:$V$5001,orders_clean!$N$2:$N$5001,A37) -> 786912 | D37: =COUNTIFS(orders_clean!$N$2:$N$5001,A37) -> 333
A38: 6 | B38: Jun | C38: =SUMIFS(orders_clean!$V$2:$V$5001,orders_clean!$N$2:$N$5001,A38) -> 793841.15 | D38: =COUNTIFS(orders_clean!$N$2:$N$5001,A38) -> 300
A39: 7 | B39: Jul | C39: =SUMIFS(orders_clean!$V$2:$V$5001,orders_clean!$N$2:$N$5001,A39) -> 873631.5 | D39: =COUNTIFS(orders_clean!$N$2:$N$5001,A39) -> 371
A40: 8 | B40: Aug | C40: =SUMIFS(orders_clean!$V$2:$V$5001,orders_clean!$N$2:$N$5001,A40) -> 1203393.2 | D40: =COUNTIFS(orders_clean!$N$2:$N$5001,A40) -> 410
A41: 9 | B41: Sep | C41: =SUMIFS(orders_clean!$V$2:$V$5001,orders_clean!$N$2:$N$5001,A41) -> 1543639.4 | D41: =COUNTIFS(orders_clean!$N$2:$N$5001,A41) -> 468
A42: 10 | B42: Oct | C42: =SUMIFS(orders_clean!$V$2:$V$5001,orders_clean!$N$2:$N$5001,A42) -> 1978317 | D42: =COUNTIFS(orders_clean!$N$2:$N$5001,A42) -> 637
A43: 11 | B43: Nov | C43: =SUMIFS(orders_clean!$V$2:$V$5001,orders_clean!$N$2:$N$5001,A43) -> 1965664.4 | D43: =COUNTIFS(orders_clean!$N$2:$N$5001,A43) -> 620
A44: 12 | B44: Dec | C44: =SUMIFS(orders_clean!$V$2:$V$5001,orders_clean!$N$2:$N$5001,A44) -> 1558902.1 | D44: =COUNTIFS(orders_clean!$N$2:$N$5001,A44) -> 526

Sheet Pivot_check
A1: Formula version of the pivot table (Rows: city_clean, Columns: category, Values: SUM of revenue)
A3: city | B3: Electronics | C3: Fashion | D3: Home | E3: Beauty | F3: Books | G3: Grand total
A4: Delhi | B4: =SUMIFS(orders_clean!$V$2:$V$5001,orders_clean!$P$2:$P$5001,$A4,orders_clean!$W$2:$W$5001,B$3) -> 1118941.9 | C4: =SUMIFS(orders_clean!$V$2:$V$5001,orders_clean!$P$2:$P$5001,$A4,orders_clean!$W$2:$W$5001,C$3) -> 526306.2 | D4: =SUMIFS(orders_clean!$V$2:$V$5001,orders_clean!$P$2:$P$5001,$A4,orders_clean!$W$2:$W$5001,D$3) -> 419223.55 | E4: =SUMIFS(orders_clean!$V$2:$V$5001,orders_clean!$P$2:$P$5001,$A4,orders_clean!$W$2:$W$5001,E$3) -> 136721.3 | F4: =SUMIFS(orders_clean!$V$2:$V$5001,orders_clean!$P$2:$P$5001,$A4,orders_clean!$W$2:$W$5001,F$3) -> 122212.4 | G4: =SUM(B4:F4) -> 2323405.4
A5: Bengaluru | B5: =SUMIFS(orders_clean!$V$2:$V$5001,orders_clean!$P$2:$P$5001,$A5,orders_clean!$W$2:$W$5001,B$3) -> 1160942.4 | C5: =SUMIFS(orders_clean!$V$2:$V$5001,orders_clean!$P$2:$P$5001,$A5,orders_clean!$W$2:$W$5001,C$3) -> 516667 | D5: =SUMIFS(orders_clean!$V$2:$V$5001,orders_clean!$P$2:$P$5001,$A5,orders_clean!$W$2:$W$5001,D$3) -> 358141.1 | E5: =SUMIFS(orders_clean!$V$2:$V$5001,orders_clean!$P$2:$P$5001,$A5,orders_clean!$W$2:$W$5001,E$3) -> 127868.7 | F5: =SUMIFS(orders_clean!$V$2:$V$5001,orders_clean!$P$2:$P$5001,$A5,orders_clean!$W$2:$W$5001,F$3) -> 92994 | G5: =SUM(B5:F5) -> 2256613.2
A6: Mumbai | B6: =SUMIFS(orders_clean!$V$2:$V$5001,orders_clean!$P$2:$P$5001,$A6,orders_clean!$W$2:$W$5001,B$3) -> 955525.15 | C6: =SUMIFS(orders_clean!$V$2:$V$5001,orders_clean!$P$2:$P$5001,$A6,orders_clean!$W$2:$W$5001,C$3) -> 463504 | D6: =SUMIFS(orders_clean!$V$2:$V$5001,orders_clean!$P$2:$P$5001,$A6,orders_clean!$W$2:$W$5001,D$3) -> 401668.85 | E6: =SUMIFS(orders_clean!$V$2:$V$5001,orders_clean!$P$2:$P$5001,$A6,orders_clean!$W$2:$W$5001,E$3) -> 141933.9 | F6: =SUMIFS(orders_clean!$V$2:$V$5001,orders_clean!$P$2:$P$5001,$A6,orders_clean!$W$2:$W$5001,F$3) -> 127574.1 | G6: =SUM(B6:F6) -> 2090206
A7: Hyderabad | B7: =SUMIFS(orders_clean!$V$2:$V$5001,orders_clean!$P$2:$P$5001,$A7,orders_clean!$W$2:$W$5001,B$3) -> 757993 | C7: =SUMIFS(orders_clean!$V$2:$V$5001,orders_clean!$P$2:$P$5001,$A7,orders_clean!$W$2:$W$5001,C$3) -> 264688.35 | D7: =SUMIFS(orders_clean!$V$2:$V$5001,orders_clean!$P$2:$P$5001,$A7,orders_clean!$W$2:$W$5001,D$3) -> 292564.2 | E7: =SUMIFS(orders_clean!$V$2:$V$5001,orders_clean!$P$2:$P$5001,$A7,orders_clean!$W$2:$W$5001,E$3) -> 106800.7 | F7: =SUMIFS(orders_clean!$V$2:$V$5001,orders_clean!$P$2:$P$5001,$A7,orders_clean!$W$2:$W$5001,F$3) -> 72570.5 | G7: =SUM(B7:F7) -> 1494616.8
A8: Pune | B8: =SUMIFS(orders_clean!$V$2:$V$5001,orders_clean!$P$2:$P$5001,$A8,orders_clean!$W$2:$W$5001,B$3) -> 705290.6 | C8: =SUMIFS(orders_clean!$V$2:$V$5001,orders_clean!$P$2:$P$5001,$A8,orders_clean!$W$2:$W$5001,C$3) -> 323324.3 | D8: =SUMIFS(orders_clean!$V$2:$V$5001,orders_clean!$P$2:$P$5001,$A8,orders_clean!$W$2:$W$5001,D$3) -> 246468.3 | E8: =SUMIFS(orders_clean!$V$2:$V$5001,orders_clean!$P$2:$P$5001,$A8,orders_clean!$W$2:$W$5001,E$3) -> 52753.8 | F8: =SUMIFS(orders_clean!$V$2:$V$5001,orders_clean!$P$2:$P$5001,$A8,orders_clean!$W$2:$W$5001,F$3) -> 59861.3 | G8: =SUM(B8:F8) -> 1387698.3
A9: Chennai | B9: =SUMIFS(orders_clean!$V$2:$V$5001,orders_clean!$P$2:$P$5001,$A9,orders_clean!$W$2:$W$5001,B$3) -> 753000.1 | C9: =SUMIFS(orders_clean!$V$2:$V$5001,orders_clean!$P$2:$P$5001,$A9,orders_clean!$W$2:$W$5001,C$3) -> 241824.55 | D9: =SUMIFS(orders_clean!$V$2:$V$5001,orders_clean!$P$2:$P$5001,$A9,orders_clean!$W$2:$W$5001,D$3) -> 218498.65 | E9: =SUMIFS(orders_clean!$V$2:$V$5001,orders_clean!$P$2:$P$5001,$A9,orders_clean!$W$2:$W$5001,E$3) -> 55511.95 | F9: =SUMIFS(orders_clean!$V$2:$V$5001,orders_clean!$P$2:$P$5001,$A9,orders_clean!$W$2:$W$5001,F$3) -> 64723.65 | G9: =SUM(B9:F9) -> 1333558.9
A10: Kolkata | B10: =SUMIFS(orders_clean!$V$2:$V$5001,orders_clean!$P$2:$P$5001,$A10,orders_clean!$W$2:$W$5001,B$3) -> 655912.9 | C10: =SUMIFS(orders_clean!$V$2:$V$5001,orders_clean!$P$2:$P$5001,$A10,orders_clean!$W$2:$W$5001,C$3) -> 223887.5 | D10: =SUMIFS(orders_clean!$V$2:$V$5001,orders_clean!$P$2:$P$5001,$A10,orders_clean!$W$2:$W$5001,D$3) -> 220579.2 | E10: =SUMIFS(orders_clean!$V$2:$V$5001,orders_clean!$P$2:$P$5001,$A10,orders_clean!$W$2:$W$5001,E$3) -> 93873.95 | F10: =SUMIFS(orders_clean!$V$2:$V$5001,orders_clean!$P$2:$P$5001,$A10,orders_clean!$W$2:$W$5001,F$3) -> 42950.65 | G10: =SUM(B10:F10) -> 1237204.2
A11: Ahmedabad | B11: =SUMIFS(orders_clean!$V$2:$V$5001,orders_clean!$P$2:$P$5001,$A11,orders_clean!$W$2:$W$5001,B$3) -> 625324.1 | C11: =SUMIFS(orders_clean!$V$2:$V$5001,orders_clean!$P$2:$P$5001,$A11,orders_clean!$W$2:$W$5001,C$3) -> 186263.85 | D11: =SUMIFS(orders_clean!$V$2:$V$5001,orders_clean!$P$2:$P$5001,$A11,orders_clean!$W$2:$W$5001,D$3) -> 160823.5 | E11: =SUMIFS(orders_clean!$V$2:$V$5001,orders_clean!$P$2:$P$5001,$A11,orders_clean!$W$2:$W$5001,E$3) -> 47560.2 | F11: =SUMIFS(orders_clean!$V$2:$V$5001,orders_clean!$P$2:$P$5001,$A11,orders_clean!$W$2:$W$5001,F$3) -> 45071.4 | G11: =SUM(B11:F11) -> 1065043.1
